using System;

namespace ExceptionTutorial {
    class Program {
        static void Main(string[] args) {
            //execute Level 1
            try {
                Level1(3);
            }catch (Exception ex) {
                //message below will not show if you do not trap exception where it occurred
                Console.WriteLine("The program encountered an exception");
                Console.WriteLine($"Exception : {ex.Message}");


            }
            //message below will not show if you do not trap exception
            Console.WriteLine("Done...");
        }
        //Adding 3 new methods
        static void Level1(int i) {
            //execute level2
            Level2(i - 1);

        }
        static void Level2(int i) {
            Level3(i - 2);
            var result = 100 / i;
            Console.WriteLine($"result is {result}");
        }   //execute level 3

        static void Level3(int i) {
            //line 21 was problem for exception(dividing by zero) 
            //try {
                //try block
                var result = 100 / i;
                //exception is generated by dividing 100 by zero
                Console.WriteLine($"result is {result}");

                // catch block
            } //catch (DivideByZeroException ex) {
               // Console.WriteLine(ex.Message);
            }
               
             }
                
        
    
